nohup: ignoring input
‚ùå Ultimate AI bot runtime error: Cannot close a running event loop
Traceback (most recent call last):
  File "/workspace/venv/lib/python3.13/site-packages/telegram/ext/_application.py", line 1049, in __run
    loop.run_until_complete(self._bootstrap_initialize(max_retries=bootstrap_retries))
    ~~~~~~~~~~~~~~~~~~~~~~~^^^^^^^^^^^^^^^^^^^^^^^^^^^^^^^^^^^^^^^^^^^^^^^^^^^^^^^^^^^
  File "/usr/lib/python3.13/asyncio/base_events.py", line 695, in run_until_complete
    self._check_running()
    ~~~~~~~~~~~~~~~~~~~^^
  File "/usr/lib/python3.13/asyncio/base_events.py", line 631, in _check_running
    raise RuntimeError('This event loop is already running')
RuntimeError: This event loop is already running

During handling of the above exception, another exception occurred:

Traceback (most recent call last):
  File "/workspace/venv/lib/python3.13/site-packages/telegram/ext/_application.py", line 1074, in __run
    loop.run_until_complete(self.shutdown())
    ~~~~~~~~~~~~~~~~~~~~~~~^^^^^^^^^^^^^^^^^
  File "/usr/lib/python3.13/asyncio/base_events.py", line 695, in run_until_complete
    self._check_running()
    ~~~~~~~~~~~~~~~~~~~^^
  File "/usr/lib/python3.13/asyncio/base_events.py", line 631, in _check_running
    raise RuntimeError('This event loop is already running')
RuntimeError: This event loop is already running

During handling of the above exception, another exception occurred:

Traceback (most recent call last):
  File "/workspace/ultimate_ai_trading_bot.py", line 1263, in <module>
    asyncio.run(bot.run())
    ~~~~~~~~~~~^^^^^^^^^^^
  File "/usr/lib/python3.13/asyncio/runners.py", line 195, in run
    return runner.run(main)
           ~~~~~~~~~~^^^^^^
  File "/usr/lib/python3.13/asyncio/runners.py", line 118, in run
    return self._loop.run_until_complete(task)
           ~~~~~~~~~~~~~~~~~~~~~~~~~~~~~^^^^^^
  File "/usr/lib/python3.13/asyncio/base_events.py", line 719, in run_until_complete
    return future.result()
           ~~~~~~~~~~~~~^^
  File "/workspace/ultimate_ai_trading_bot.py", line 1251, in run
    await self.application.run_polling(drop_pending_updates=True)
          ~~~~~~~~~~~~~~~~~~~~~~~~~~~~^^^^^^^^^^^^^^^^^^^^^^^^^^^
  File "/workspace/venv/lib/python3.13/site-packages/telegram/ext/_application.py", line 839, in run_polling
    return self.__run(
           ~~~~~~~~~~^
        updater_coroutine=self.updater.start_polling(
        ^^^^^^^^^^^^^^^^^^^^^^^^^^^^^^^^^^^^^^^^^^^^^
    ...<9 lines>...
        close_loop=close_loop,
        ^^^^^^^^^^^^^^^^^^^^^^
    )
    ^
  File "/workspace/venv/lib/python3.13/site-packages/telegram/ext/_application.py", line 1079, in __run
    loop.close()
    ~~~~~~~~~~^^
  File "/usr/lib/python3.13/asyncio/unix_events.py", line 70, in close
    super().close()
    ~~~~~~~~~~~~~^^
  File "/usr/lib/python3.13/asyncio/selector_events.py", line 101, in close
    raise RuntimeError("Cannot close a running event loop")
RuntimeError: Cannot close a running event loop
<sys>:0: RuntimeWarning: coroutine 'Application.shutdown' was never awaited
<sys>:0: RuntimeWarning: coroutine 'Application._bootstrap_initialize' was never awaited
